{
    "output": "",
    "errors": "FFF.FF..\n======================================================================\nFAIL: test_alternating_movements (__main__.TestAntMovement.test_alternating_movements)\n----------------------------------------------------------------------\nTraceback (most recent call last):\n  File \"C:\\Users\\Serge\\Desktop\\GPT-Testing\\DataSets\\DataSet-New\\LeetCodeTasks - Testing\\Tests\\3028_ant-on-the-boundary\\test.py\", line 107, in test_alternating_movements\n    self.assertEqual(result, expected)\nAssertionError: 0 != 7\n\n======================================================================\nFAIL: test_boundary_cross (__main__.TestAntMovement.test_boundary_cross)\n----------------------------------------------------------------------\nTraceback (most recent call last):\n  File \"C:\\Users\\Serge\\Desktop\\GPT-Testing\\DataSets\\DataSet-New\\LeetCodeTasks - Testing\\Tests\\3028_ant-on-the-boundary\\test.py\", line 47, in test_boundary_cross\n    self.assertEqual(result, expected)\nAssertionError: 0 != 3\n\n======================================================================\nFAIL: test_example1 (__main__.TestAntMovement.test_example1)\n----------------------------------------------------------------------\nTraceback (most recent call last):\n  File \"C:\\Users\\Serge\\Desktop\\GPT-Testing\\DataSets\\DataSet-New\\LeetCodeTasks - Testing\\Tests\\3028_ant-on-the-boundary\\test.py\", line 23, in test_example1\n    self.assertEqual(result, expected)\nAssertionError: 0 != 1\n\n======================================================================\nFAIL: test_large_movements (__main__.TestAntMovement.test_large_movements)\n----------------------------------------------------------------------\nTraceback (most recent call last):\n  File \"C:\\Users\\Serge\\Desktop\\GPT-Testing\\DataSets\\DataSet-New\\LeetCodeTasks - Testing\\Tests\\3028_ant-on-the-boundary\\test.py\", line 83, in test_large_movements\n    self.assertEqual(result, expected)\nAssertionError: 0 != 5\n\n======================================================================\nFAIL: test_multiple_returns (__main__.TestAntMovement.test_multiple_returns)\n----------------------------------------------------------------------\nTraceback (most recent call last):\n  File \"C:\\Users\\Serge\\Desktop\\GPT-Testing\\DataSets\\DataSet-New\\LeetCodeTasks - Testing\\Tests\\3028_ant-on-the-boundary\\test.py\", line 71, in test_multiple_returns\n    self.assertEqual(result, expected)\nAssertionError: 0 != 5\n\n----------------------------------------------------------------------\nRan 8 tests in 0.018s\n\nFAILED (failures=5)\n",
    "returncode": 1
}