{
    "output": "",
    "errors": "FF..FFF.\n======================================================================\nFAIL: test_alternating_movements (__main__.TestAntMovement.test_alternating_movements)\n----------------------------------------------------------------------\nTraceback (most recent call last):\n  File \"C:\\Users\\Serge\\Desktop\\GPT-Testing\\DataSets\\DataSet-New\\LeetCodeTasks - Testing\\Tests\\3028_ant-on-the-boundary\\test.py\", line 107, in test_alternating_movements\n    self.assertEqual(result, expected)\nAssertionError: 4 != 7\n\n======================================================================\nFAIL: test_boundary_cross (__main__.TestAntMovement.test_boundary_cross)\n----------------------------------------------------------------------\nTraceback (most recent call last):\n  File \"C:\\Users\\Serge\\Desktop\\GPT-Testing\\DataSets\\DataSet-New\\LeetCodeTasks - Testing\\Tests\\3028_ant-on-the-boundary\\test.py\", line 47, in test_boundary_cross\n    self.assertEqual(result, expected)\nAssertionError: 2 != 3\n\n======================================================================\nFAIL: test_large_movements (__main__.TestAntMovement.test_large_movements)\n----------------------------------------------------------------------\nTraceback (most recent call last):\n  File \"C:\\Users\\Serge\\Desktop\\GPT-Testing\\DataSets\\DataSet-New\\LeetCodeTasks - Testing\\Tests\\3028_ant-on-the-boundary\\test.py\", line 83, in test_large_movements\n    self.assertEqual(result, expected)\nAssertionError: 3 != 5\n\n======================================================================\nFAIL: test_multiple_returns (__main__.TestAntMovement.test_multiple_returns)\n----------------------------------------------------------------------\nTraceback (most recent call last):\n  File \"C:\\Users\\Serge\\Desktop\\GPT-Testing\\DataSets\\DataSet-New\\LeetCodeTasks - Testing\\Tests\\3028_ant-on-the-boundary\\test.py\", line 71, in test_multiple_returns\n    self.assertEqual(result, expected)\nAssertionError: 3 != 5\n\n======================================================================\nFAIL: test_negative_movements (__main__.TestAntMovement.test_negative_movements)\n----------------------------------------------------------------------\nTraceback (most recent call last):\n  File \"C:\\Users\\Serge\\Desktop\\GPT-Testing\\DataSets\\DataSet-New\\LeetCodeTasks - Testing\\Tests\\3028_ant-on-the-boundary\\test.py\", line 95, in test_negative_movements\n    self.assertEqual(result, expected)\nAssertionError: 1 != 0\n\n----------------------------------------------------------------------\nRan 8 tests in 0.002s\n\nFAILED (failures=5)\n",
    "returncode": 1
}