{
    "output": "",
    "errors": "FFF.FF\n======================================================================\nFAIL: test_example1 (__main__.TestLargestSquareArea.test_example1)\n----------------------------------------------------------------------\nTraceback (most recent call last):\n  File \"C:\\Users\\Serge\\Desktop\\GPT-Testing\\DataSets\\DataSet-New\\LeetCodeTasks - Testing\\Tests\\3047_find-the-largest-area-of-square-inside-two-rectangles\\test.py\", line 21, in test_example1\n    self.assertEqual(self.solution.largestSquareArea(bottomLeft, topRight), 1)\nAssertionError: 25 != 1\n\n======================================================================\nFAIL: test_example2 (__main__.TestLargestSquareArea.test_example2)\n----------------------------------------------------------------------\nTraceback (most recent call last):\n  File \"C:\\Users\\Serge\\Desktop\\GPT-Testing\\DataSets\\DataSet-New\\LeetCodeTasks - Testing\\Tests\\3047_find-the-largest-area-of-square-inside-two-rectangles\\test.py\", line 31, in test_example2\n    self.assertEqual(self.solution.largestSquareArea(bottomLeft, topRight), 1)\nAssertionError: 9 != 1\n\n======================================================================\nFAIL: test_example3 (__main__.TestLargestSquareArea.test_example3)\n----------------------------------------------------------------------\nTraceback (most recent call last):\n  File \"C:\\Users\\Serge\\Desktop\\GPT-Testing\\DataSets\\DataSet-New\\LeetCodeTasks - Testing\\Tests\\3047_find-the-largest-area-of-square-inside-two-rectangles\\test.py\", line 41, in test_example3\n    self.assertEqual(self.solution.largestSquareArea(bottomLeft, topRight), 0)\nAssertionError: 9 != 0\n\n======================================================================\nFAIL: test_no_intersection (__main__.TestLargestSquareArea.test_no_intersection)\n----------------------------------------------------------------------\nTraceback (most recent call last):\n  File \"C:\\Users\\Serge\\Desktop\\GPT-Testing\\DataSets\\DataSet-New\\LeetCodeTasks - Testing\\Tests\\3047_find-the-largest-area-of-square-inside-two-rectangles\\test.py\", line 51, in test_no_intersection\n    self.assertEqual(self.solution.largestSquareArea(bottomLeft, topRight), 0)\nAssertionError: 25 != 0\n\n======================================================================\nFAIL: test_partial_overlap (__main__.TestLargestSquareArea.test_partial_overlap)\n----------------------------------------------------------------------\nTraceback (most recent call last):\n  File \"C:\\Users\\Serge\\Desktop\\GPT-Testing\\DataSets\\DataSet-New\\LeetCodeTasks - Testing\\Tests\\3047_find-the-largest-area-of-square-inside-two-rectangles\\test.py\", line 71, in test_partial_overlap\n    self.assertEqual(self.solution.largestSquareArea(bottomLeft, topRight), 4)\nAssertionError: 36 != 4\n\n----------------------------------------------------------------------\nRan 6 tests in 0.002s\n\nFAILED (failures=5)\n",
    "returncode": 1
}